<sdf version='1.7'>
  <model name='pi_robot'>
    <link name='base_link'>
      <inertial>
        <pose>0 0 0.05 0 -0 0</pose>
        <mass>10</mass>
        <inertia>
          <ixx>0.4</ixx>
          <ixy>0</ixy>
          <ixz>0</ixz>
          <iyy>0.4</iyy>
          <iyz>0</iyz>
          <izz>0.2</izz>
        </inertia>
      </inertial>
      <collision name='base_link_collision'>
        <pose>0 0 0.05 0 -0 0</pose>
        <geometry>
          <box>
            <size>0.5 0.5 0.1</size>
          </box>
        </geometry>
        <surface>
          <contact>
            <ode/>
          </contact>
          <friction>
            <ode>
              <mu>0.02</mu>
              <mu2>0.02</mu2>
            </ode>
          </friction>
        </surface>
      </collision>
      <visual name='base_link_visual'>
        <pose>0 0 0.05 0 -0 0</pose>
        <geometry>
          <box>
            <size>0.5 0.5 0.1</size>
          </box>
        </geometry>
        <material>
          <script>
            <name>Gazebo/Blue</name>
            <uri>file://media/materials/scripts/gazebo.material</uri>
          </script>
        </material>
      </visual>
      <gravity>1</gravity>
      <velocity_decay/>
    </link>
    <joint name='leg1joint' type='revolute'>
      <pose relative_to='base_link'>0 0.3 0.07 0 -0 0</pose>
      <parent>base_link</parent>
      <child>leg1</child>
      <axis>
        <xyz>1 0 0</xyz>
        <limit>
          <lower>-0.3</lower>
          <upper>1.2</upper>
          <effort>1000</effort>
          <velocity>0.5</velocity>
        </limit>
        <dynamics>
          <damping>0.7</damping>
          <friction>0</friction>
          <spring_reference>0</spring_reference>
          <spring_stiffness>0</spring_stiffness>
        </dynamics>
      </axis>
    </joint>
    <link name='leg1'>
      <pose relative_to='leg1joint'>0 0 0 0 -0 0</pose>
      <inertial>
        <pose>0 0.25 0 0 -0 0</pose>
        <mass>0.2</mass>
        <inertia>
          <ixx>0.1</ixx>
          <ixy>0</ixy>
          <ixz>0</ixz>
          <iyy>0.1</iyy>
          <iyz>0</iyz>
          <izz>0.1</izz>
        </inertia>
      </inertial>
      <collision name='leg1_collision'>
        <pose>0 0.25 0 0 -0 0</pose>
        <geometry>
          <box>
            <size>0.1 0.5 0.1</size>
          </box>
        </geometry>
      </collision>
      <visual name='leg1_visual'>
        <pose>0 0.25 0 0 -0 0</pose>
        <geometry>
          <box>
            <size>0.1 0.5 0.1</size>
          </box>
        </geometry>
      </visual>
    </link>
    <joint name='leg2joint' type='revolute'>
      <pose relative_to='leg1'>0 0.5 0.05 0 -0 0</pose>
      <parent>leg1</parent>
      <child>leg2</child>
      <axis>
        <xyz>1 0 0</xyz>
        <limit>
          <lower>-1.8</lower>
          <upper>0.5</upper>
          <effort>1000</effort>
          <velocity>0.5</velocity>
        </limit>
        <dynamics>
          <damping>0.7</damping>
          <friction>0</friction>
          <spring_reference>0</spring_reference>
          <spring_stiffness>0</spring_stiffness>
        </dynamics>
      </axis>
    </joint>
    <link name='leg2'>
      <pose relative_to='leg2joint'>0 0 0 0 -0 0</pose>
      <inertial>
        <pose>0 0.25 0 0 -0 0</pose>
        <mass>0.2</mass>
        <inertia>
          <ixx>0.1</ixx>
          <ixy>0</ixy>
          <ixz>0</ixz>
          <iyy>0.1</iyy>
          <iyz>0</iyz>
          <izz>0.1</izz>
        </inertia>
      </inertial>
      <collision name='leg2_collision'>
        <pose>0 0.25 0 0 -0 0</pose>
        <geometry>
          <box>
            <size>0.1 0.5 0.1</size>
          </box>
        </geometry>
        <surface>
          <contact>
            <ode/>
          </contact>
          <friction>
            <ode>
              <mu>0.2</mu>
              <mu2>0.2</mu2>
            </ode>
          </friction>
        </surface>
      </collision>
      <visual name='leg2_visual'>
        <pose>0 0.25 0 0 -0 0</pose>
        <geometry>
          <box>
            <size>0.1 0.5 0.1</size>
          </box>
        </geometry>
        <material>
          <script>
            <name>Gazebo/Black</name>
            <uri>file://media/materials/scripts/gazebo.material</uri>
          </script>
        </material>
      </visual>
      <gravity>1</gravity>
      <velocity_decay/>
    </link>
  </model>
</sdf>
