<robot name="crawler_robot">

	<!-- * * * Link Definitions * * * -->

	<link name="base_link">
		<visual>
			<origin xyz="0 0 0.05" rpy="0 0 0" />
			<geometry>
				<box size="1 2 0.1" />
			</geometry>
			<material name="Grey">
				<color rgba="0 0.2 0.2 1.0" />
			</material>
		</visual>
		<inertial>
			<mass value="5" />
			<origin xyz="0 0 0.05" rpy="0 0 0" />
			<inertia ixx="0.4" ixy="0.0" ixz="0.0" iyy="0.4" iyz="0.0" izz="0.2" />
		</inertial>
		<collision>
			<origin xyz="0 0 0.05" rpy="0 0 0" />
			<geometry>
				<box size="0.5 0.5 0.1" />
			</geometry>
		</collision>
	</link>

	<gazebo reference="base_link">
		<mu1>0.02</mu1>
		<mu2>0.02</mu2>
		<material>Gazebo/Blue</material>
	</gazebo>


	<link name="leg1">
		<visual>
			<origin xyz="0 0.45 0.0" rpy="0 0 0" />
			<geometry>
				<box size="0.1 0.9 0.1" />
			</geometry>
			<material name="Cyan1">
				<color rgba="0 0.9 0.9 1.0" />
			</material>
		</visual>
		<inertial>
			<origin xyz="0 0.45 0.0" rpy="0 0 0" />
			<mass value="0.2" />
			<inertia ixx="0.1" ixy="0.0" ixz="0.0" iyy="0.1" iyz="0.0" izz="0.1" />
		</inertial>
		<collision>

			<origin xyz="0 0.45 0.0" rpy="0 0 0" />
			<geometry>
				<box size="0.1 0.9 0.1" />
			</geometry>
		</collision>
	</link>

	<link name="leg2">
		<visual>
			<origin xyz="0 0.5 0.0" rpy="0 0 0" />
			<geometry>
				<box size="0.1 1 0.3" />
			</geometry>
			<material name="blue">
				<color rgba="0 0.1 0.9 1.0" />
			</material>
		</visual>
		<inertial>
			<origin xyz="0 0.25 0.0" rpy="0 0 0" />
			<mass value="0.2" />
			<inertia ixx="0.1" ixy="0.0" ixz="0.0" iyy="0.1" iyz="0.0" izz="0.1" />
		</inertial>
		<collision>
			<origin xyz="0 0.5 0.0" rpy="0 0 0" />
			<geometry>
				<box size="0.1 1 0.3" />
			</geometry>
		</collision>
	</link>

	<gazebo reference="leg2">
		<mu1>0.2</mu1>
		<mu2>0.2</mu2>
		<material>Gazebo/Black</material>
	</gazebo>


	<joint name="leg1joint" type="revolute">
		<parent link="base_link" />
		<child link="leg1" />
		<limit effort="10000" lower="0.0" upper="1.57" velocity="0.5" />
		<axis xyz="1 0 0" />
		<origin xyz="0 0.8 0.2" />
		<dynamics damping="0.2" />
	</joint>

	<joint name="leg2joint" type="revolute">
		<parent link="leg1" />
		<child link="leg2" />
		<limit effort="10000" lower="-1.57" upper="0.0" velocity="0.5" />
		<axis xyz="1 0 0" />
		<origin xyz="0.1 0.8 0.0" />
		<dynamics damping="0.2" />
	</joint>
</robot> 
